Workbook
Name UPDATE: 'Data Sheet'!$E$1

Sheet Profit & Loss
A1: ='Data Sheet'!B1 -> HINDUSTAN UNILEVER LTD | H1: =UPDATE | M1: SCREENER.IN
A3: Narration | B3: ='Data Sheet'!B16 -> 42460 | C3: ='Data Sheet'!C16 -> 42825 | D3: ='Data Sheet'!D16 -> 43190 | E3: ='Data Sheet'!E16 -> 43555 | F3: ='Data Sheet'!F16 -> 43921 | G3: ='Data Sheet'!G16 -> 44286 | H3: ='Data Sheet'!H16 -> 44651 | I3: ='Data Sheet'!I16 -> 45016 | ... K3: ='Data Sheet'!K16 -> 45747 | L3: Trailing | M3: Best Case | N3: Worst Case
A4: Sales | B4: ='Data Sheet'!B17 -> 32186 | C4: ='Data Sheet'!C17 -> 33162 | D4: ='Data Sheet'!D17 -> 35545 | E4: ='Data Sheet'!E17 -> 39310 | F4: ='Data Sheet'!F17 -> 39783 | G4: ='Data Sheet'!G17 -> 47028 | H4: ='Data Sheet'!H17 -> 52446 | I4: ='Data Sheet'!I17 -> 60580 | ... K4: ='Data Sheet'!K17 -> 63121 | L4: =SUM(Quarters!H4:K4) -> 63121 | M4: =$K4+M23*K4 -> 67142.015 | N4: =$K4+N23*L4 -> 64370.244
A5: Expenses | B5: =SUM('Data Sheet'!B18,'Data Sheet'!B20:B24, -1*'Data Sheet'!B19) -> 26276 | C5: =SUM('Data Sheet'!C18,'Data Sheet'!C20:C24, -1*'Data Sheet'!C19) -> 26834 | D5: =SUM('Data Sheet'!D18,'Data Sheet'!D20:D24, -1*'Data Sheet'!D19) -> 28046 | E5: =SUM('Data Sheet'!E18,'Data Sheet'!E20:E24, -1*'Data Sheet'!E19) -> 30430 | F5: =SUM('Data Sheet'!F18,'Data Sheet'!F20:F24, -1*'Data Sheet'!F19) -> 29922 | G5: =SUM('Data Sheet'!G18,'Data Sheet'!G20:G24, -1*'Data Sheet'!G19) -> 35402 | H5: =SUM('Data Sheet'!H18,'Data Sheet'!H20:H24, -1*'Data Sheet'!H19) -> 39589 | I5: =SUM('Data Sheet'!I18,'Data Sheet'!I20:I24, -1*'Data Sheet'!I19) -> 46433 | ... K5: =SUM('Data Sheet'!K18,'Data Sheet'!K20:K24, -1*'Data Sheet'!K19) -> 48278 | L5: =SUM(Quarters!H5:K5) -> 48279 | M5: =M4-M6 -> 51351.448 | N5: =N4-N6 -> 49613.963
A6: Operating Profit | B6: =B4-B5 -> 5910 | C6: =C4-C5 -> 6328 | D6: =D4-D5 -> 7499 | E6: =E4-E5 -> 8880 | F6: =F4-F5 -> 9861 | G6: =G4-G5 -> 11626 | H6: =H4-H5 -> 12857 | I6: =I4-I5 -> 14147 | ... K6: =K4-K5 -> 14843 | L6: =SUM(Quarters!H6:K6) -> 14842 | M6: =M4*M24 -> 15790.567 | N6: =N4*N24 -> 14756.281
A7: Other Income | B7: ='Data Sheet'!B25 -> 486 | C7: ='Data Sheet'!C25 -> 606 | D7: ='Data Sheet'!D25 -> 353 | E7: ='Data Sheet'!E25 -> 322 | F7: ='Data Sheet'!F25 -> 424 | G7: ='Data Sheet'!G25 -> 170 | H7: ='Data Sheet'!H25 -> 219 | I7: ='Data Sheet'!I25 -> 448 | ... K7: ='Data Sheet'!K25 -> 1322 | L7: =SUM(Quarters!H7:K7) -> 1323 | M7: 0 | N7: 0
A8: Depreciation | B8: ='Data Sheet'!B26 -> 353 | C8: ='Data Sheet'!C26 -> 432 | D8: ='Data Sheet'!D26 -> 520 | E8: ='Data Sheet'!E26 -> 565 | F8: ='Data Sheet'!F26 -> 1002 | G8: ='Data Sheet'!G26 -> 1074 | H8: ='Data Sheet'!H26 -> 1091 | I8: ='Data Sheet'!I26 -> 1137 | ... K8: ='Data Sheet'!K26 -> 1355 | L8: =SUM(Quarters!H8:K8) -> 1355 | M8: =+$L8 -> 1355 | N8: =+$L8 -> 1355
A9: Interest | B9: ='Data Sheet'!B27 -> 17 | C9: ='Data Sheet'!C27 -> 35 | D9: ='Data Sheet'!D27 -> 26 | E9: ='Data Sheet'!E27 -> 33 | F9: ='Data Sheet'!F27 -> 118 | G9: ='Data Sheet'!G27 -> 117 | H9: ='Data Sheet'!H27 -> 106 | I9: ='Data Sheet'!I27 -> 114 | ... K9: ='Data Sheet'!K27 -> 395 | L9: =SUM(Quarters!H9:K9) -> 395 | M9: =+$L9 -> 395 | N9: =+$L9 -> 395
A10: Profit before tax | B10: ='Data Sheet'!B28 -> 6026 | C10: ='Data Sheet'!C28 -> 6467 | D10: ='Data Sheet'!D28 -> 7306 | E10: ='Data Sheet'!E28 -> 8604 | F10: ='Data Sheet'!F28 -> 9165 | G10: ='Data Sheet'!G28 -> 10605 | H10: ='Data Sheet'!H28 -> 11879 | I10: ='Data Sheet'!I28 -> 13344 | ... K10: ='Data Sheet'!K28 -> 14415 | L10: =SUM(Quarters!H10:K10) -> 14415 | M10: =M6+M7-SUM(M8:M9) -> 14040.567 | N10: =N6+N7-SUM(N8:N9) -> 13006.281
A11: Tax | B11: ='Data Sheet'!B29 -> 1875 | C11: ='Data Sheet'!C29 -> 1977 | D11: ='Data Sheet'!D29 -> 2079 | E11: ='Data Sheet'!E29 -> 2544 | F11: ='Data Sheet'!F29 -> 2409 | G11: ='Data Sheet'!G29 -> 2606 | H11: ='Data Sheet'!H29 -> 2987 | I11: ='Data Sheet'!I29 -> 3201 | ... K11: ='Data Sheet'!K29 -> 3744 | L11: =SUM(Quarters!H11:K11) -> 3744 | M11: =IF($L10>0,$L11/$L10,0) -> 0.25972945 | N11: =IF($L10>0,$L11/$L10,0) -> 0.25972945
A12: Net profit | B12: ='Data Sheet'!B30 -> 4151 | C12: ='Data Sheet'!C30 -> 4476 | D12: ='Data Sheet'!D30 -> 5214 | E12: ='Data Sheet'!E30 -> 6054 | F12: ='Data Sheet'!F30 -> 6748 | G12: ='Data Sheet'!G30 -> 7995 | H12: ='Data Sheet'!H30 -> 8879 | I12: ='Data Sheet'!I30 -> 10120 | ... K12: ='Data Sheet'!K30 -> 10649 | L12: =SUM(Quarters!H12:K12) -> 10649 | M12: =M10-M11*M10 -> 10393.818 | N12: =N10-N11*N10 -> 9628.1668
A13: EPS | B13: =IF('Data Sheet'!B93>0,B12/'Data Sheet'!B93,0) -> 19.182957 | C13: =IF('Data Sheet'!C93>0,C12/'Data Sheet'!C93,0) -> 20.681052 | D13: =IF('Data Sheet'!D93>0,D12/'Data Sheet'!D93,0) -> 24.088704 | E13: =IF('Data Sheet'!E93>0,E12/'Data Sheet'!E93,0) -> 27.966924 | F13: =IF('Data Sheet'!F93>0,F12/'Data Sheet'!F93,0) -> 31.171471 | G13: =IF('Data Sheet'!G93>0,G12/'Data Sheet'!G93,0) -> 34.027068 | H13: =IF('Data Sheet'!H93>0,H12/'Data Sheet'!H93,0) -> 37.789411 | I13: =IF('Data Sheet'!I93>0,I12/'Data Sheet'!I93,0) -> 43.071161 | ... K13: =IF('Data Sheet'!K93>0,K12/'Data Sheet'!K93,0) -> 45.322608 | L13: =IF('Data Sheet'!$B6>0,'Profit & Loss'!L12/'Data Sheet'!$B6,0) -> 45.292593 | M13: =IF('Data Sheet'!$B6>0,'Profit & Loss'!M12/'Data Sheet'!$B6,0) -> 44.207246 | N13: =IF('Data Sheet'!$B6>0,'Profit & Loss'!N12/'Data Sheet'!$B6,0) -> 40.950759
A14: Price to earning | B14: =IF(B15>0,B15/B13,"") -> 45.326694 | C14: =IF(C15>0,C15/C13,"") -> 44.086249 | D14: =IF(D15>0,D15/D13,"") -> 55.35167 | E14: =IF(E15>0,E15/E13,"") -> 61.029236 | F14: =IF(F15>0,F15/F13,"") -> 73.737297 | G14: =IF(G15>0,G15/G13,"") -> 71.457816 | H14: =IF(H15>0,H15/H13,"") -> 54.212277 | I14: =IF(I15>0,I15/I13,"") -> 59.444648 | ... K14: =IF(K15>0,K15/K13,"") -> 49.839365 | L14: =IF(L13>0,L15/L13,0) -> 51.412381 | M14: =M25 -> 53.116389 | N14: =N25 -> 51.412381
A15: Price | B15: ='Data Sheet'!B90 -> 869.5 | C15: ='Data Sheet'!C90 -> 911.75 | D15: ='Data Sheet'!D90 -> 1333.35 | E15: ='Data Sheet'!E90 -> 1706.8 | F15: ='Data Sheet'!F90 -> 2298.5 | G15: ='Data Sheet'!G90 -> 2431.5 | H15: ='Data Sheet'!H90 -> 2048.65 | I15: ='Data Sheet'!I90 -> 2560.35 | ... K15: ='Data Sheet'!K90 -> 2258.85 | L15: ='Data Sheet'!B8 -> 2328.6 | M15: =M13*M14 -> 2348.1293 | N15: =N13*N14 -> 2105.376
A17: RATIOS:
A18: Dividend Payout | B18: =IF('Data Sheet'!B30>0, 'Data Sheet'!B31/'Data Sheet'!B30, 0) -> 0.83257046 | C18: =IF('Data Sheet'!C30>0, 'Data Sheet'!C31/'Data Sheet'!C30, 0) -> 0.82037534 | D18: =IF('Data Sheet'!D30>0, 'Data Sheet'!D31/'Data Sheet'!D30, 0) -> 0.82853855 | E18: =IF('Data Sheet'!E30>0, 'Data Sheet'!E31/'Data Sheet'!E30, 0) -> 0.78493558 | F18: =IF('Data Sheet'!F30>0, 'Data Sheet'!F31/'Data Sheet'!F30, 0) -> 0.80023711 | G18: =IF('Data Sheet'!G30>0, 'Data Sheet'!G31/'Data Sheet'!G30, 0) -> 1.1904315 | H18: =IF('Data Sheet'!H30>0, 'Data Sheet'!H31/'Data Sheet'!H30, 0) -> 0.89987611 | I18: =IF('Data Sheet'!I30>0, 'Data Sheet'!I31/'Data Sheet'!I30, 0) -> 0.90563241 | ... K18: =IF('Data Sheet'!K30>0, 'Data Sheet'!K31/'Data Sheet'!K30, 0) -> 1.1695934
A19: OPM | B19: =IF(B6>0,B6/B4,0) -> 0.18362021 | C19: =IF(C6>0,C6/C4,0) -> 0.19082082 | D19: =IF(D6>0,D6/D4,0) -> 0.21097201 | E19: =IF(E6>0,E6/E4,0) -> 0.22589672 | F19: =IF(F6>0,F6/F4,0) -> 0.24786969 | G19: =IF(G6>0,G6/G4,0) -> 0.24721443 | H19: =IF(H6>0,H6/H4,0) -> 0.24514739 | I19: =IF(I6>0,I6/I4,0) -> 0.23352592 | ... L19: =IF(L6>0,L6/L4,0) -> 0.23513569
G22: TRENDS: | H22: 10 YEARS | I22: 7 YEARS | J22: 5 YEARS | K22: 3 YEARS | L22: RECENT | M22: BEST | N22: WORST
G23: Sales Growth | H23: =IF(B4=0,"",POWER($K4/B4,1/9)-1) -> 0.077707146 | I23: =IF(D4=0,"",POWER($K4/D4,1/7)-1) -> 0.0854952 | J23: =IF(F4=0,"",POWER($K4/F4,1/5)-1) -> 0.096718749 | K23: =IF(H4=0,"",POWER($K4/H4, 1/3)-1) -> 0.063703284 | L23: =IF(ISERROR(MAX(IF(J4=0,"",(K4-J4)/J4),IF(K4=0,"",(L4-K4)/K4))),"",MAX(IF(J4=0,"",(K4-J4)/J4),IF(K4=0,"",(L4-K4)/K4))) -> 0.019791263 | M23: =MAX(K23:L23) -> 0.063703284 | N23: =MIN(H23:L23) -> 0.019791263
G24: OPM | H24: =IF(SUM(B4:$K$4)=0,"",SUMPRODUCT(B19:$K$19,B4:$K$4)/SUM(B4:$K$4)) -> 0.22924072 | I24: =IF(SUM(E4:$K$4)=0,"",SUMPRODUCT(E19:$K$19,E4:$K$4)/SUM(E4:$K$4)) -> 0.23855461 | J24: =IF(SUM(G4:$K$4)=0,"",SUMPRODUCT(G19:$K$19,G4:$K$4)/SUM(G4:$K$4)) -> 0.23900011 | K24: =IF(SUM(I4:$K$4)=0, "", SUMPRODUCT(I19:$K$19,I4:$K$4)/SUM(I4:$K$4)) -> 0.2351816 | L24: =L19 -> 0.23513569 | M24: =MAX(K24:L24) -> 0.2351816 | N24: =MIN(H24:L24) -> 0.22924072
G25: Price to Earning | H25: =IF(ISERROR(AVERAGEIF(B14:$L14,">0")),"",AVERAGEIF(B14:$L14,">0")) -> 56.151527 | I25: =IF(ISERROR(AVERAGEIF(E14:$L14,">0")),"",AVERAGEIF(E14:$L14,">0")) -> 59.112773 | J25: =IF(ISERROR(AVERAGEIF(G14:$L14,">0")),"",AVERAGEIF(G14:$L14,">0")) -> 56.355941 | K25: =IF(ISERROR(AVERAGEIF(I14:$L14,">0")),"",AVERAGEIF(I14:$L14,">0")) -> 53.116389 | L25: =L14 -> 51.412381 | M25: =MAX(K25:L25) -> 53.116389 | N25: =MIN(H25:L25) -> 51.412381

Sheet Quarters
A1: ='Profit & Loss'!A1 -> HINDUSTAN UNILEVER LTD | E1: =UPDATE | J1: SCREENER.IN
A3: Narration | B3: ='Data Sheet'!B41 -> 44926 | C3: ='Data Sheet'!C41 -> 45016 | D3: ='Data Sheet'!D41 -> 45107 | E3: ='Data Sheet'!E41 -> 45199 | F3: ='Data Sheet'!F41 -> 45291 | G3: ='Data Sheet'!G41 -> 45382 | H3: ='Data Sheet'!H41 -> 45473 | I3: ='Data Sheet'!I41 -> 45565 | ... K3: ='Data Sheet'!K41 -> 45747
A4: Sales | B4: ='Data Sheet'!B42 -> 15597 | C4: ='Data Sheet'!C42 -> 15215 | D4: ='Data Sheet'!D42 -> 15496 | E4: ='Data Sheet'!E42 -> 15623 | F4: ='Data Sheet'!F42 -> 15567 | G4: ='Data Sheet'!G42 -> 15210 | H4: ='Data Sheet'!H42 -> 15707 | I4: ='Data Sheet'!I42 -> 15926 | ... K4: ='Data Sheet'!K42 -> 15670
A5: Expenses | B5: ='Data Sheet'!B43 -> 11903 | C5: ='Data Sheet'!C43 -> 11643 | D5: ='Data Sheet'!D43 -> 11832 | E5: ='Data Sheet'!E43 -> 11828 | F5: ='Data Sheet'!F43 -> 11902 | G5: ='Data Sheet'!G43 -> 11675 | H5: ='Data Sheet'!H43 -> 11965 | I5: ='Data Sheet'!I43 -> 12139 | ... K5: ='Data Sheet'!K43 -> 12052
A6: Operating Profit | B6: ='Data Sheet'!B50 -> 3694 | C6: ='Data Sheet'!C50 -> 3572 | D6: ='Data Sheet'!D50 -> 3664 | E6: ='Data Sheet'!E50 -> 3795 | F6: ='Data Sheet'!F50 -> 3665 | G6: ='Data Sheet'!G50 -> 3535 | H6: ='Data Sheet'!H50 -> 3742 | I6: ='Data Sheet'!I50 -> 3787 | ... K6: ='Data Sheet'!K50 -> 3618
A7: Other Income | B7: ='Data Sheet'!B44 -> 7 | C7: ='Data Sheet'!C44 -> 240 | D7: ='Data Sheet'!D44 -> 146 | E7: ='Data Sheet'!E44 -> 178 | F7: ='Data Sheet'!F44 -> 184 | G7: ='Data Sheet'!G44 -> 309 | H7: ='Data Sheet'!H44 -> 209 | I7: ='Data Sheet'!I44 -> 203 | ... K7: ='Data Sheet'!K44 -> 171
A8: Depreciation | B8: ='Data Sheet'!B45 -> 293 | C8: ='Data Sheet'!C45 -> 291 | D8: ='Data Sheet'!D45 -> 286 | E8: ='Data Sheet'!E45 -> 297 | F8: ='Data Sheet'!F45 -> 313 | G8: ='Data Sheet'!G45 -> 320 | H8: ='Data Sheet'!H45 -> 329 | I8: ='Data Sheet'!I45 -> 338 | ... K8: ='Data Sheet'!K45 -> 347
A9: Interest | B9: ='Data Sheet'!B46 -> 29 | C9: ='Data Sheet'!C46 -> 29 | D9: ='Data Sheet'!D46 -> 50 | E9: ='Data Sheet'!E46 -> 88 | F9: ='Data Sheet'!F46 -> 91 | G9: ='Data Sheet'!G46 -> 105 | H9: ='Data Sheet'!H46 -> 93 | I9: ='Data Sheet'!I46 -> 110 | ... K9: ='Data Sheet'!K46 -> 80
A10: Profit before tax | B10: ='Data Sheet'!B47 -> 3379 | C10: ='Data Sheet'!C47 -> 3492 | D10: ='Data Sheet'!D47 -> 3474 | E10: ='Data Sheet'!E47 -> 3588 | F10: ='Data Sheet'!F47 -> 3445 | G10: ='Data Sheet'!G47 -> 3419 | H10: ='Data Sheet'!H47 -> 3529 | I10: ='Data Sheet'!I47 -> 3542 | ... K10: ='Data Sheet'!K47 -> 3362
A11: Tax | B11: ='Data Sheet'!B48 -> 898 | C11: ='Data Sheet'!C48 -> 891 | D11: ='Data Sheet'!D48 -> 918 | E11: ='Data Sheet'!E48 -> 931 | F11: ='Data Sheet'!F48 -> 937 | G11: ='Data Sheet'!G48 -> 858 | H11: ='Data Sheet'!H48 -> 917 | I11: ='Data Sheet'!I48 -> 947 | ... K11: ='Data Sheet'!K48 -> 887
A12: Net profit | B12: ='Data Sheet'!B49 -> 2474 | C12: ='Data Sheet'!C49 -> 2600 | D12: ='Data Sheet'!D49 -> 2554 | E12: ='Data Sheet'!E49 -> 2656 | F12: ='Data Sheet'!F49 -> 2509 | G12: ='Data Sheet'!G49 -> 2558 | H12: ='Data Sheet'!H49 -> 2610 | I12: ='Data Sheet'!I49 -> 2591 | ... K12: ='Data Sheet'!K49 -> 2464
A14: OPM | B14: =IF(B4>0,B6/B4,"") -> 0.23684042 | C14: =IF(C4>0,C6/C4,"") -> 0.23476832 | D14: =IF(D4>0,D6/D4,"") -> 0.23644812 | E14: =IF(E4>0,E6/E4,"") -> 0.24291109 | F14: =IF(F4>0,F6/F4,"") -> 0.23543393 | G14: =IF(G4>0,G6/G4,"") -> 0.23241289 | H14: =IF(H4>0,H6/H4,"") -> 0.23823773 | I14: =IF(I4>0,I6/I4,"") -> 0.23778727 | ... K14: =IF(K4>0,K6/K4,"") -> 0.23088705

Sheet Balance Sheet
A1: ='Profit & Loss'!A1 -> HINDUSTAN UNILEVER LTD | E1: =UPDATE | J1: SCREENER.IN
A3: Narration | B3: ='Data Sheet'!B56 -> 42460 | C3: ='Data Sheet'!C56 -> 42825 | D3: ='Data Sheet'!D56 -> 43190 | E3: ='Data Sheet'!E56 -> 43555 | F3: ='Data Sheet'!F56 -> 43921 | G3: ='Data Sheet'!G56 -> 44286 | H3: ='Data Sheet'!H56 -> 44651 | I3: ='Data Sheet'!I56 -> 45016 | ... K3: ='Data Sheet'!K56 -> 45747
A4: Equity Share Capital | B4: ='Data Sheet'!B57 -> 216 | C4: ='Data Sheet'!C57 -> 216 | D4: ='Data Sheet'!D57 -> 216 | E4: ='Data Sheet'!E57 -> 216 | F4: ='Data Sheet'!F57 -> 216 | G4: ='Data Sheet'!G57 -> 235 | H4: ='Data Sheet'!H57 -> 235 | I4: ='Data Sheet'!I57 -> 235 | ... K4: ='Data Sheet'!K57 -> 235
A5: Reserves | B5: ='Data Sheet'!B58 -> 6357 | C5: ='Data Sheet'!C58 -> 6528 | D5: ='Data Sheet'!D58 -> 7065 | E5: ='Data Sheet'!E58 -> 7651 | F5: ='Data Sheet'!F58 -> 8013 | G5: ='Data Sheet'!G58 -> 47439 | H5: ='Data Sheet'!H58 -> 48826 | I5: ='Data Sheet'!I58 -> 50069 | ... K5: ='Data Sheet'!K58 -> 49167
A6: Borrowings | B6: ='Data Sheet'!B59 -> 177 | C6: ='Data Sheet'!C59 -> 277 | D6: ='Data Sheet'!D59 -> 0 | E6: ='Data Sheet'!E59 -> 99 | F6: ='Data Sheet'!F59 -> 0 | G6: ='Data Sheet'!G59 -> 0 | H6: ='Data Sheet'!H59 -> 1043 | I6: ='Data Sheet'!I59 -> 1219 | ... K6: ='Data Sheet'!K59 -> 1648
A7: Other Liabilities | B7: ='Data Sheet'!B60 -> 8043 | C7: ='Data Sheet'!C60 -> 8685 | D7: ='Data Sheet'!D60 -> 10581 | E7: ='Data Sheet'!E60 -> 10663 | F7: ='Data Sheet'!F60 -> 11924 | G7: ='Data Sheet'!G60 -> 21066 | H7: ='Data Sheet'!H60 -> 20402 | I7: ='Data Sheet'!I60 -> 21554 | ... K7: ='Data Sheet'!K60 -> 28813
A8: Total | B8: ='Data Sheet'!B61 -> 14793 | C8: ='Data Sheet'!C61 -> 15706 | D8: ='Data Sheet'!D61 -> 17862 | E8: ='Data Sheet'!E61 -> 18629 | F8: ='Data Sheet'!F61 -> 20153 | G8: ='Data Sheet'!G61 -> 68740 | H8: ='Data Sheet'!H61 -> 70506 | I8: ='Data Sheet'!I61 -> 73077 | ... K8: ='Data Sheet'!K61 -> 79863
A10: Net Block | B10: ='Data Sheet'!B62 -> 3258 | C10: ='Data Sheet'!C62 -> 4419 | D10: ='Data Sheet'!D62 -> 4528 | E10: ='Data Sheet'!E62 -> 4715 | F10: ='Data Sheet'!F62 -> 5479 | G10: ='Data Sheet'!G62 -> 51443 | H10: ='Data Sheet'!H62 -> 51473 | I10: ='Data Sheet'!I62 -> 52678 | ... K10: ='Data Sheet'!K62 -> 54335
A11: Capital Work in Progress | B11: ='Data Sheet'!B63 -> 408 | C11: ='Data Sheet'!C63 -> 229 | D11: ='Data Sheet'!D63 -> 461 | E11: ='Data Sheet'!E63 -> 406 | F11: ='Data Sheet'!F63 -> 597 | G11: ='Data Sheet'!G63 -> 745 | H11: ='Data Sheet'!H63 -> 1313 | I11: ='Data Sheet'!I63 -> 1132 | ... K11: ='Data Sheet'!K63 -> 1009
A12: Investments | B12: ='Data Sheet'!B64 -> 2592 | C12: ='Data Sheet'!C64 -> 3794 | D12: ='Data Sheet'!D64 -> 2873 | E12: ='Data Sheet'!E64 -> 2716 | F12: ='Data Sheet'!F64 -> 1255 | G12: ='Data Sheet'!G64 -> 2709 | H12: ='Data Sheet'!H64 -> 3521 | I12: ='Data Sheet'!I64 -> 2882 | ... K12: ='Data Sheet'!K64 -> 3810
A13: Other Assets | B13: ='Data Sheet'!B65 -> 8535 | C13: ='Data Sheet'!C65 -> 7264 | D13: ='Data Sheet'!D65 -> 10000 | E13: ='Data Sheet'!E65 -> 10792 | F13: ='Data Sheet'!F65 -> 12822 | G13: ='Data Sheet'!G65 -> 13843 | H13: ='Data Sheet'!H65 -> 14199 | I13: ='Data Sheet'!I65 -> 16385 | ... K13: ='Data Sheet'!K65 -> 20709
A14: Total | B14: ='Data Sheet'!B66 -> 14793 | C14: ='Data Sheet'!C66 -> 15706 | D14: ='Data Sheet'!D66 -> 17862 | E14: ='Data Sheet'!E66 -> 18629 | F14: ='Data Sheet'!F66 -> 20153 | G14: ='Data Sheet'!G66 -> 68740 | H14: ='Data Sheet'!H66 -> 70506 | I14: ='Data Sheet'!I66 -> 73077 | ... K14: ='Data Sheet'!K66 -> 79863
A16: Working Capital | B16: =B13-B7 -> 492 | C16: =C13-C7 -> -1421 | D16: =D13-D7 -> -581 | E16: =E13-E7 -> 129 | F16: =F13-F7 -> 898 | G16: =G13-G7 -> -7223 | H16: =H13-H7 -> -6203 | I16: =I13-I7 -> -5169 | ... K16: =K13-K7 -> -8104
A17: Debtors | B17: ='Data Sheet'!B67 -> 1264 | C17: ='Data Sheet'!C67 -> 1085 | D17: ='Data Sheet'!D67 -> 1310 | E17: ='Data Sheet'!E67 -> 1816 | F17: ='Data Sheet'!F67 -> 1149 | G17: ='Data Sheet'!G67 -> 1758 | H17: ='Data Sheet'!H67 -> 2236 | I17: ='Data Sheet'!I67 -> 3079 | ... K17: ='Data Sheet'!K67 -> 3819
A18: Inventory | B18: ='Data Sheet'!B68 -> 2726 | C18: ='Data Sheet'!C68 -> 2541 | D18: ='Data Sheet'!D68 -> 2513 | E18: ='Data Sheet'!E68 -> 2574 | F18: ='Data Sheet'!F68 -> 2767 | G18: ='Data Sheet'!G68 -> 3579 | H18: ='Data Sheet'!H68 -> 4096 | I18: ='Data Sheet'!I68 -> 4251 | ... K18: ='Data Sheet'!K68 -> 4415
A20: Debtor Days | B20: =IF('Profit & Loss'!B4>0,'Balance Sheet'!B17/('Profit & Loss'!B4/365),0) -> 14.334183 | C20: =IF('Profit & Loss'!C4>0,'Balance Sheet'!C17/('Profit & Loss'!C4/365),0) -> 11.942133 | D20: =IF('Profit & Loss'!D4>0,'Balance Sheet'!D17/('Profit & Loss'!D4/365),0) -> 13.451962 | E20: =IF('Profit & Loss'!E4>0,'Balance Sheet'!E17/('Profit & Loss'!E4/365),0) -> 16.861867 | F20: =IF('Profit & Loss'!F4>0,'Balance Sheet'!F17/('Profit & Loss'!F4/365),0) -> 10.541814 | G20: =IF('Profit & Loss'!G4>0,'Balance Sheet'!G17/('Profit & Loss'!G4/365),0) -> 13.644425 | H20: =IF('Profit & Loss'!H4>0,'Balance Sheet'!H17/('Profit & Loss'!H4/365),0) -> 15.56153 | I20: =IF('Profit & Loss'!I4>0,'Balance Sheet'!I17/('Profit & Loss'!I4/365),0) -> 18.551255 | ... K20: =IF('Profit & Loss'!K4>0,'Balance Sheet'!K17/('Profit & Loss'!K4/365),0) -> 22.083538
A21: Inventory Turnover | B21: =IF('Balance Sheet'!B18>0,'Profit & Loss'!B4/'Balance Sheet'!B18,0) -> 11.807043 | C21: =IF('Balance Sheet'!C18>0,'Profit & Loss'!C4/'Balance Sheet'!C18,0) -> 13.050767 | D21: =IF('Balance Sheet'!D18>0,'Profit & Loss'!D4/'Balance Sheet'!D18,0) -> 14.144449 | E21: =IF('Balance Sheet'!E18>0,'Profit & Loss'!E4/'Balance Sheet'!E18,0) -> 15.27195 | F21: =IF('Balance Sheet'!F18>0,'Profit & Loss'!F4/'Balance Sheet'!F18,0) -> 14.377665 | G21: =IF('Balance Sheet'!G18>0,'Profit & Loss'!G4/'Balance Sheet'!G18,0) -> 13.139983 | H21: =IF('Balance Sheet'!H18>0,'Profit & Loss'!H4/'Balance Sheet'!H18,0) -> 12.804199 | I21: =IF('Balance Sheet'!I18>0,'Profit & Loss'!I4/'Balance Sheet'!I18,0) -> 14.250765 | ... K21: =IF('Balance Sheet'!K18>0,'Profit & Loss'!K4/'Balance Sheet'!K18,0) -> 14.296942
A23: Return on Equity | B23: =IF(SUM('Balance Sheet'!B4:B5)>0,'Profit & Loss'!B12/SUM('Balance Sheet'!B4:B5),"") -> 0.6315229 | C23: =IF(SUM('Balance Sheet'!C4:C5)>0,'Profit & Loss'!C12/SUM('Balance Sheet'!C4:C5),"") -> 0.66370107 | D23: =IF(SUM('Balance Sheet'!D4:D5)>0,'Profit & Loss'!D12/SUM('Balance Sheet'!D4:D5),"") -> 0.71611042 | E23: =IF(SUM('Balance Sheet'!E4:E5)>0,'Profit & Loss'!E12/SUM('Balance Sheet'!E4:E5),"") -> 0.76954366 | F23: =IF(SUM('Balance Sheet'!F4:F5)>0,'Profit & Loss'!F12/SUM('Balance Sheet'!F4:F5),"") -> 0.82002673 | G23: =IF(SUM('Balance Sheet'!G4:G5)>0,'Profit & Loss'!G12/SUM('Balance Sheet'!G4:G5),"") -> 0.16770147 | H23: =IF(SUM('Balance Sheet'!H4:H5)>0,'Profit & Loss'!H12/SUM('Balance Sheet'!H4:H5),"") -> 0.18097878 | I23: =IF(SUM('Balance Sheet'!I4:I5)>0,'Profit & Loss'!I12/SUM('Balance Sheet'!I4:I5),"") -> 0.20117684 | ... K23: =IF(SUM('Balance Sheet'!K4:K5)>0,'Profit & Loss'!K12/SUM('Balance Sheet'!K4:K5),"") -> 0.21555807
A24: Return on Capital Emp | C24: =IF((B4+B5+B6+C4+C5+C6)>0,('Profit & Loss'!C10+'Profit & Loss'!C9)*2/(B4+B5+B6+C4+C5+C6),"") -> 0.94430325 | D24: =IF((C4+C5+C6+D4+D5+D6)>0,('Profit & Loss'!D10+'Profit & Loss'!D9)*2/(C4+C5+C6+D4+D5+D6),"") -> 1.0253111 | E24: =IF((D4+D5+D6+E4+E5+E6)>0,('Profit & Loss'!E10+'Profit & Loss'!E9)*2/(D4+D5+D6+E4+E5+E6),"") -> 1.1329442 | F24: =IF((E4+E5+E6+F4+F5+F6)>0,('Profit & Loss'!F10+'Profit & Loss'!F9)*2/(E4+E5+E6+F4+F5+F6),"") -> 1.1464032 | G24: =IF((F4+F5+F6+G4+G5+G6)>0,('Profit & Loss'!G10+'Profit & Loss'!G9)*2/(F4+F5+F6+G4+G5+G6),"") -> 0.38359301 | H24: =IF((G4+G5+G6+H4+H5+H6)>0,('Profit & Loss'!H10+'Profit & Loss'!H9)*2/(G4+G5+G6+H4+H5+H6),"") -> 0.24514717 | I24: =IF((H4+H5+H6+I4+I5+I6)>0,('Profit & Loss'!I10+'Profit & Loss'!I9)*2/(H4+H5+H6+I4+I5+I6),"") -> 0.26485088 | J24: =IF((I4+I5+I6+J4+J5+J6)>0,('Profit & Loss'!J10+'Profit & Loss'!J9)*2/(I4+I5+I6+J4+J5+J6),"") -> 0.27363876 | K24: =IF((J4+J5+J6+K4+K5+K6)>0,('Profit & Loss'!K10+'Profit & Loss'!K9)*2/(J4+J5+J6+K4+K5+K6),"") -> 0.28548847

Sheet Cash Flow
A1: ='Balance Sheet'!A1 -> HINDUSTAN UNILEVER LTD | E1: =UPDATE | J1: SCREENER.IN
A3: Narration | B3: ='Data Sheet'!B81 -> 42460 | C3: ='Data Sheet'!C81 -> 42825 | D3: ='Data Sheet'!D81 -> 43190 | E3: ='Data Sheet'!E81 -> 43555 | F3: ='Data Sheet'!F81 -> 43921 | G3: ='Data Sheet'!G81 -> 44286 | H3: ='Data Sheet'!H81 -> 44651 | I3: ='Data Sheet'!I81 -> 45016 | ... K3: ='Data Sheet'!K81 -> 45747
A4: Cash from Operating Activity | B4: ='Data Sheet'!B82 -> 4171 | C4: ='Data Sheet'!C82 -> 5185 | D4: ='Data Sheet'!D82 -> 6059 | E4: ='Data Sheet'!E82 -> 5800 | F4: ='Data Sheet'!F82 -> 7623 | G4: ='Data Sheet'!G82 -> 9163 | H4: ='Data Sheet'!H82 -> 9048 | I4: ='Data Sheet'!I82 -> 9991 | ... K4: ='Data Sheet'!K82 -> 11886
A5: Cash from Investing Activity | B5: ='Data Sheet'!B83 -> -282 | C5: ='Data Sheet'!C83 -> -1173 | D5: ='Data Sheet'!D83 -> -1063 | E5: ='Data Sheet'!E83 -> -438 | F5: ='Data Sheet'!F83 -> 1791 | G5: ='Data Sheet'!G83 -> -1228 | H5: ='Data Sheet'!H83 -> -1728 | I5: ='Data Sheet'!I83 -> -1484 | ... K5: ='Data Sheet'!K83 -> 6473
A6: Cash from Financing Activity | B6: ='Data Sheet'!B84 -> -3864 | C6: ='Data Sheet'!C84 -> -4214 | D6: ='Data Sheet'!D84 -> -4975 | E6: ='Data Sheet'!E84 -> -5390 | F6: ='Data Sheet'!F84 -> -6819 | G6: ='Data Sheet'!G84 -> -9309 | H6: ='Data Sheet'!H84 -> -8015 | I6: ='Data Sheet'!I84 -> -8953 | ... K6: ='Data Sheet'!K84 -> -13101
A7: Net Cash Flow | B7: ='Data Sheet'!B85 -> 25 | C7: ='Data Sheet'!C85 -> -202 | D7: ='Data Sheet'!D85 -> 21 | E7: ='Data Sheet'!E85 -> -28 | F7: ='Data Sheet'!F85 -> 2595 | G7: ='Data Sheet'!G85 -> -1374 | H7: ='Data Sheet'!H85 -> -695 | I7: ='Data Sheet'!I85 -> -446 | ... K7: ='Data Sheet'!K85 -> 5258

Sheet Customization
A1: How to use it?
A3: You can customize this workbook as you want.
B4: You can add custom formating, add conditional formating, add your own formulas… do ANYTHING.
B5: Please don't edit the "Data Sheet" only.
A7: After customization, you can upload this back on Screener.
B8: Upload on: | C8: https://www.screener.in/excel/
A10: Download your customized workbooks now onwards.
B11: Now whenever you will "Export to excel" from Screener, it will export your customized file.
A14: TESTING:
B15: This is a testing feature currently.
B16: You can report any formula errors on the worksheet at: support@screener.in

Sheet Historical FS
B2: ="Historical Financial Statements for "&'Data Sheet'!$B$1 -> Historical Financial Statements for HINDUSTAN UNILEVER LTD
B3: Year | C3: ='Data Sheet'!B16 -> 42460 | D3: ='Data Sheet'!C16 -> 42825 | E3: ='Data Sheet'!D16 -> 43190 | F3: ='Data Sheet'!E16 -> 43555 | G3: ='Data Sheet'!F16 -> 43921 | H3: ='Data Sheet'!G16 -> 44286 | I3: ='Data Sheet'!H16 -> 44651 | J3: ='Data Sheet'!I16 -> 45016 | ... L3: ='Data Sheet'!K16 -> 45747 | M3: ='Data Sheet'!K56+365 -> 46112 | N3: =M3+365 -> 46477 | O3: =N3+365 -> 46842 | P3: =O3+365 -> 47207 | Q3: =P3+365 -> 47572
A5: # | B5: Income Statement
B6: ='Data Sheet'!A17 -> Sales | C6: ='Data Sheet'!B17 -> 32186 | D6: ='Data Sheet'!C17 -> 33162 | E6: ='Data Sheet'!D17 -> 35545 | F6: ='Data Sheet'!E17 -> 39310 | G6: ='Data Sheet'!F17 -> 39783 | H6: ='Data Sheet'!G17 -> 47028 | I6: ='Data Sheet'!H17 -> 52446 | ... L6: ='Data Sheet'!K17 -> 63121 | M6: =FORECAST(M$3,$C6:$L6,$C$3:$L$3) -> 68216.751 | N6: =FORECAST(N$3,$C6:$L6,$C$3:$L$3) -> 72161.857 | O6: =FORECAST(O$3,$C6:$L6,$C$3:$L$3) -> 76106.962 | P6: =FORECAST(P$3,$C6:$L6,$C$3:$L$3) -> 80052.068 | Q6: =FORECAST(Q$3,$C6:$L6,$C$3:$L$3) -> 83997.174 | S6: =((L6/C6)^(1/10))-1 -> 0.069672144
B7: Sales Growth | C7: - | D7: =D6/C6-1 -> 0.030323743 | E7: =E6/D6-1 -> 0.071859357 | F7: =F6/E6-1 -> 0.10592207 | G7: =G6/F6-1 -> 0.012032562 | H7: =H6/G6-1 -> 0.18211296 | I7: =I6/H6-1 -> 0.11520796 | J7: =J6/I6-1 -> 0.15509286 | K7: =K6/J6-1 -> 0.021723341 | ... Q7: =Q6/P6-1 -> 0.049281745
B9: COGS | C9: =SUM('Data Sheet'!B18,'Data Sheet'!B20:B22)-(1*'Data Sheet'!B19) -> 18222 | D9: =SUM('Data Sheet'!C18,'Data Sheet'!C20:C22)-(1*'Data Sheet'!C19) -> 18675 | E9: =SUM('Data Sheet'!D18,'Data Sheet'!D20:D22)-(1*'Data Sheet'!D19) -> 19314 | F9: =SUM('Data Sheet'!E18,'Data Sheet'!E20:E22)-(1*'Data Sheet'!E19) -> 21081 | G9: =SUM('Data Sheet'!F18,'Data Sheet'!F20:F22)-(1*'Data Sheet'!F19) -> 20614 | H9: =SUM('Data Sheet'!G18,'Data Sheet'!G20:G22)-(1*'Data Sheet'!G19) -> 25301 | I9: =SUM('Data Sheet'!H18,'Data Sheet'!H20:H22)-(1*'Data Sheet'!H19) -> 29066 | J9: =SUM('Data Sheet'!I18,'Data Sheet'!I20:I22)-(1*'Data Sheet'!I19) -> 35381 | ... L9: =SUM('Data Sheet'!K18,'Data Sheet'!K20:K22)-(1*'Data Sheet'!K19) -> 34529 | M9: =FORECAST(M$3,$C9:$L9,$C$3:$L$3) -> 37601.367 | N9: =FORECAST(N$3,$C9:$L9,$C$3:$L$3) -> 39785.146 | O9: =FORECAST(O$3,$C9:$L9,$C$3:$L$3) -> 41968.926 | P9: =FORECAST(P$3,$C9:$L9,$C$3:$L$3) -> 44152.705 | Q9: =FORECAST(Q$3,$C9:$L9,$C$3:$L$3) -> 46336.485
B11: Gross Profit | C11: =C6-C9 -> 13964 | D11: =D6-D9 -> 14487 | E11: =E6-E9 -> 16231 | F11: =F6-F9 -> 18229 | G11: =G6-G9 -> 19169 | H11: =H6-H9 -> 21727 | I11: =I6-I9 -> 23380 | J11: =J6-J9 -> 25199 | ... L11: =L6-L9 -> 28592 | M11: =FORECAST(M$3,$C11:$L11,$C$3:$L$3) -> 30615.384 | N11: =FORECAST(N$3,$C11:$L11,$C$3:$L$3) -> 32376.71 | O11: =FORECAST(O$3,$C11:$L11,$C$3:$L$3) -> 34138.037 | P11: =FORECAST(P$3,$C11:$L11,$C$3:$L$3) -> 35899.363 | Q11: =FORECAST(Q$3,$C11:$L11,$C$3:$L$3) -> 37660.689
B12: Gross Profit Margins | C12: =C11/C6 -> 0.43385323 | D12: =D11/D6 -> 0.43685544 | E12: =E11/E6 -> 0.45663244 | F12: =F11/F6 -> 0.46372424 | G12: =G11/G6 -> 0.48183898 | H12: =H11/H6 -> 0.46200136 | I12: =I11/I6 -> 0.44579186 | J12: =J11/J6 -> 0.41596236 | ... Q12: =Q11/Q6 -> 0.44835662
B14: Selling and General expenses | C14: =SUM('Data Sheet'!B23:B24) -> 8054 | D14: =SUM('Data Sheet'!C23:C24) -> 8159 | E14: =SUM('Data Sheet'!D23:D24) -> 8732 | F14: =SUM('Data Sheet'!E23:E24) -> 9349 | G14: =SUM('Data Sheet'!F23:F24) -> 9308 | H14: =SUM('Data Sheet'!G23:G24) -> 10101 | I14: =SUM('Data Sheet'!H23:H24) -> 10523 | J14: =SUM('Data Sheet'!I23:I24) -> 11052 | ... L14: =SUM('Data Sheet'!K23:K24) -> 13749 | M14: =FORECAST(M$3,$C14:$L14,$C$3:$L$3) -> 13766.516 | N14: =FORECAST(N$3,$C14:$L14,$C$3:$L$3) -> 14403.448 | O14: =FORECAST(O$3,$C14:$L14,$C$3:$L$3) -> 15040.379 | P14: =FORECAST(P$3,$C14:$L14,$C$3:$L$3) -> 15677.31 | Q14: =FORECAST(Q$3,$C14:$L14,$C$3:$L$3) -> 16314.241
B16: EBITDA | C16: =C11-C14 -> 5910 | D16: =D11-D14 -> 6328 | E16: =E11-E14 -> 7499 | F16: =F11-F14 -> 8880 | G16: =G11-G14 -> 9861 | H16: =H11-H14 -> 11626 | I16: =I11-I14 -> 12857 | J16: =J11-J14 -> 14147 | ... L16: =L11-L14 -> 14843 | M16: =FORECAST(M$3,$C16:$L16,$C$3:$L$3) -> 16848.868 | N16: =FORECAST(N$3,$C16:$L16,$C$3:$L$3) -> 17973.263 | O16: =FORECAST(O$3,$C16:$L16,$C$3:$L$3) -> 19097.658 | P16: =FORECAST(P$3,$C16:$L16,$C$3:$L$3) -> 20222.053 | Q16: =FORECAST(Q$3,$C16:$L16,$C$3:$L$3) -> 21346.447
B17: EBITDA Margins | C17: =C16/C6 -> 0.18362021 | D17: =D16/D6 -> 0.19082082 | E17: =E16/E6 -> 0.21097201 | F17: =F16/F6 -> 0.22589672 | G17: =G16/G6 -> 0.24786969 | H17: =H16/H6 -> 0.24721443 | I17: =I16/I6 -> 0.24514739 | J17: =J16/J6 -> 0.23352592 | ... Q17: =Q16/Q6 -> 0.25413292
B19: D&A | C19: ='Data Sheet'!B26 -> 353 | D19: ='Data Sheet'!C26 -> 432 | E19: ='Data Sheet'!D26 -> 520 | F19: ='Data Sheet'!E26 -> 565 | G19: ='Data Sheet'!F26 -> 1002 | H19: ='Data Sheet'!G26 -> 1074 | I19: ='Data Sheet'!H26 -> 1091 | J19: ='Data Sheet'!I26 -> 1137 | ... L19: ='Data Sheet'!K26 -> 1355 | M19: =FORECAST(M$3,$C19:$L19,$C$3:$L$3) -> 1515.8455 | N19: =FORECAST(N$3,$C19:$L19,$C$3:$L$3) -> 1632.3842 | O19: =FORECAST(O$3,$C19:$L19,$C$3:$L$3) -> 1748.9228 | P19: =FORECAST(P$3,$C19:$L19,$C$3:$L$3) -> 1865.4614 | Q19: =FORECAST(Q$3,$C19:$L19,$C$3:$L$3) -> 1982
B21: EBIT | C21: =C16-C19 -> 5557 | D21: =D16-D19 -> 5896 | E21: =E16-E19 -> 6979 | F21: =F16-F19 -> 8315 | G21: =G16-G19 -> 8859 | H21: =H16-H19 -> 10552 | I21: =I16-I19 -> 11766 | J21: =J16-J19 -> 13010 | ... L21: =L16-L19 -> 13488 | M21: =FORECAST(M$3,$C21:$L21,$C$3:$L$3) -> 15333.023 | N21: =FORECAST(N$3,$C21:$L21,$C$3:$L$3) -> 16340.879 | O21: =FORECAST(O$3,$C21:$L21,$C$3:$L$3) -> 17348.735 | P21: =FORECAST(P$3,$C21:$L21,$C$3:$L$3) -> 18356.591 | Q21: =FORECAST(Q$3,$C21:$L21,$C$3:$L$3) -> 19364.447
B22: EBIT Margins | C22: =C21/C6 -> 0.17265271 | D22: =D21/D6 -> 0.17779386 | E22: =E21/E6 -> 0.19634266 | F22: =F21/F6 -> 0.21152379 | G22: =G21/G6 -> 0.22268306 | H22: =H21/H6 -> 0.22437697 | I22: =I21/I6 -> 0.22434504 | J22: =J21/J6 -> 0.21475735 | ... Q22: =Q21/Q6 -> 0.23053689
B24: Interest | C24: ='Data Sheet'!B27 -> 17 | D24: ='Data Sheet'!C27 -> 35 | E24: ='Data Sheet'!D27 -> 26 | F24: ='Data Sheet'!E27 -> 33 | G24: ='Data Sheet'!F27 -> 118 | H24: ='Data Sheet'!G27 -> 117 | I24: ='Data Sheet'!H27 -> 106 | J24: ='Data Sheet'!I27 -> 114 | ... L24: ='Data Sheet'!K27 -> 395 | M24: =FORECAST(M$3,$C24:$L24,$C$3:$L$3) -> 334.61032 | N24: =FORECAST(N$3,$C24:$L24,$C$3:$L$3) -> 371.88082 | O24: =FORECAST(O$3,$C24:$L24,$C$3:$L$3) -> 409.15133 | P24: =FORECAST(P$3,$C24:$L24,$C$3:$L$3) -> 446.42183 | Q24: =FORECAST(Q$3,$C24:$L24,$C$3:$L$3) -> 483.69234
B26: EBT | C26: =C21-C24 -> 5540 | D26: =D21-D24 -> 5861 | E26: =E21-E24 -> 6953 | F26: =F21-F24 -> 8282 | G26: =G21-G24 -> 8741 | H26: =H21-H24 -> 10435 | I26: =I21-I24 -> 11660 | J26: =J21-J24 -> 12896 | ... L26: =L21-L24 -> 13093 | M26: =FORECAST(M$3,$C26:$L26,$C$3:$L$3) -> 14998.412 | N26: =FORECAST(N$3,$C26:$L26,$C$3:$L$3) -> 15968.998 | O26: =FORECAST(O$3,$C26:$L26,$C$3:$L$3) -> 16939.584 | P26: =FORECAST(P$3,$C26:$L26,$C$3:$L$3) -> 17910.169 | Q26: =FORECAST(Q$3,$C26:$L26,$C$3:$L$3) -> 18880.755
B27: EBT Margins | C27: =C26/C6 -> 0.17212453 | D27: =D26/D6 -> 0.17673844 | E27: =E26/E6 -> 0.1956112 | F27: =F26/F6 -> 0.2106843 | G27: =G26/G6 -> 0.21971696 | H27: =H26/H6 -> 0.22188909 | I27: =I26/I6 -> 0.22232391 | J27: =J26/J6 -> 0.21287554 | ... Q27: =Q26/Q6 -> 0.22477846
B29: Tax | C29: ='Data Sheet'!B29 -> 1875 | D29: ='Data Sheet'!C29 -> 1977 | E29: ='Data Sheet'!D29 -> 2079 | F29: ='Data Sheet'!E29 -> 2544 | G29: ='Data Sheet'!F29 -> 2409 | H29: ='Data Sheet'!G29 -> 2606 | I29: ='Data Sheet'!H29 -> 2987 | J29: ='Data Sheet'!I29 -> 3201 | ... L29: ='Data Sheet'!K29 -> 3744 | M29: =FORECAST(M$3,$C29:$L29,$C$3:$L$3) -> 3894.0559 | N29: =FORECAST(N$3,$C29:$L29,$C$3:$L$3) -> 4109.828 | O29: =FORECAST(O$3,$C29:$L29,$C$3:$L$3) -> 4325.6 | P29: =FORECAST(P$3,$C29:$L29,$C$3:$L$3) -> 4541.3721 | Q29: =FORECAST(Q$3,$C29:$L29,$C$3:$L$3) -> 4757.1442
B31: Net Profit | C31: =C26-C29 -> 3665 | D31: =D26-D29 -> 3884 | E31: =E26-E29 -> 4874 | F31: =F26-F29 -> 5738 | G31: =G26-G29 -> 6332 | H31: =H26-H29 -> 7829 | I31: =I26-I29 -> 8673 | J31: =J26-J29 -> 9695 | ... L31: =L26-L29 -> 9349 | M31: =FORECAST(M$3,$C31:$L31,$C$3:$L$3) -> 11104.356 | N31: =FORECAST(N$3,$C31:$L31,$C$3:$L$3) -> 11859.17 | O31: =FORECAST(O$3,$C31:$L31,$C$3:$L$3) -> 12613.984 | P31: =FORECAST(P$3,$C31:$L31,$C$3:$L$3) -> 13368.797 | Q31: =FORECAST(Q$3,$C31:$L31,$C$3:$L$3) -> 14123.611
B32: Net Profit Margins | C32: =C31/C6 -> 0.11386938 | D32: =D31/D6 -> 0.11712201 | E32: =E31/E6 -> 0.13712196 | F32: =F31/F6 -> 0.14596795 | G32: =G31/G6 -> 0.15916346 | H32: =H31/H6 -> 0.16647529 | I32: =I31/I6 -> 0.16537009 | J32: =J31/J6 -> 0.16003632 | ... Q32: =Q31/Q6 -> 0.16814388
A35: # | B35: Balance Sheet
B36: ='Data Sheet'!A57 -> Equity Share Capital | C36: ='Data Sheet'!B57 -> 216 | D36: ='Data Sheet'!C57 -> 216 | E36: ='Data Sheet'!D57 -> 216 | F36: ='Data Sheet'!E57 -> 216 | G36: ='Data Sheet'!F57 -> 216 | H36: ='Data Sheet'!G57 -> 235 | I36: ='Data Sheet'!H57 -> 235 | ... L36: ='Data Sheet'!K57 -> 235 | M36: =FORECAST(M$3,$C36:$L36,$C$3:$L$3) -> 241.33218 | N36: =FORECAST(N$3,$C36:$L36,$C$3:$L$3) -> 244.20903 | O36: =FORECAST(O$3,$C36:$L36,$C$3:$L$3) -> 247.08589 | P36: =FORECAST(P$3,$C36:$L36,$C$3:$L$3) -> 249.96275 | Q36: =FORECAST(Q$3,$C36:$L36,$C$3:$L$3) -> 252.83961
B37: ='Data Sheet'!A58 -> Reserves | C37: ='Data Sheet'!B58 -> 6357 | D37: ='Data Sheet'!C58 -> 6528 | E37: ='Data Sheet'!D58 -> 7065 | F37: ='Data Sheet'!E58 -> 7651 | G37: ='Data Sheet'!F58 -> 8013 | H37: ='Data Sheet'!G58 -> 47439 | I37: ='Data Sheet'!H58 -> 48826 | ... L37: ='Data Sheet'!K58 -> 49167 | M37: =FORECAST(M$3,$C37:$L37,$C$3:$L$3) -> 64022.056 | N37: =FORECAST(N$3,$C37:$L37,$C$3:$L$3) -> 70529.485 | O37: =FORECAST(O$3,$C37:$L37,$C$3:$L$3) -> 77036.914 | P37: =FORECAST(P$3,$C37:$L37,$C$3:$L$3) -> 83544.344 | Q37: =FORECAST(Q$3,$C37:$L37,$C$3:$L$3) -> 90051.773
B38: ='Data Sheet'!A59 -> Borrowings | C38: ='Data Sheet'!B59 -> 177 | D38: ='Data Sheet'!C59 -> 277 | E38: ='Data Sheet'!D59 -> 0 | F38: ='Data Sheet'!E59 -> 99 | G38: ='Data Sheet'!F59 -> 0 | H38: ='Data Sheet'!G59 -> 0 | I38: ='Data Sheet'!H59 -> 1043 | ... L38: ='Data Sheet'!K59 -> 1648 | M38: =FORECAST(M$3,$C38:$L38,$C$3:$L$3) -> 1615.1427 | N38: =FORECAST(N$3,$C38:$L38,$C$3:$L$3) -> 1800.5669 | O38: =FORECAST(O$3,$C38:$L38,$C$3:$L$3) -> 1985.9911 | P38: =FORECAST(P$3,$C38:$L38,$C$3:$L$3) -> 2171.4153 | Q38: =FORECAST(Q$3,$C38:$L38,$C$3:$L$3) -> 2356.8395
B39: ='Data Sheet'!A60 -> Other Liabilities | C39: ='Data Sheet'!B60-'Manual Data'!C41 -> 2358 | D39: ='Data Sheet'!C60-'Manual Data'!D41 -> 2499 | E39: ='Data Sheet'!D60-'Manual Data'!E41 -> 3411 | F39: ='Data Sheet'!E60-'Manual Data'!F41 -> 3457 | G39: ='Data Sheet'!F60-'Manual Data'!G41 -> 4389 | H39: ='Data Sheet'!G60-'Manual Data'!H41 -> 12264 | I39: ='Data Sheet'!H60-'Manual Data'!I41 -> 11334 | J39: ='Data Sheet'!I60-'Manual Data'!J41 -> 11980 | ... L39: ='Data Sheet'!K60-'Manual Data'!L41 -> 17498 | M39: =FORECAST(M$3,$C39:$L39,$C$3:$L$3) -> 18456.224 | N39: =FORECAST(N$3,$C39:$L39,$C$3:$L$3) -> 20274.614 | O39: =FORECAST(O$3,$C39:$L39,$C$3:$L$3) -> 22093.004 | P39: =FORECAST(P$3,$C39:$L39,$C$3:$L$3) -> 23911.394 | Q39: =FORECAST(Q$3,$C39:$L39,$C$3:$L$3) -> 25729.784
B40: Trade Payables | C40: ='Manual Data'!C41 -> 5685 | D40: ='Manual Data'!D41 -> 6186 | E40: ='Manual Data'!E41 -> 7170 | F40: ='Manual Data'!F41 -> 7206 | G40: ='Manual Data'!G41 -> 7535 | H40: ='Manual Data'!H41 -> 8802 | I40: ='Manual Data'!I41 -> 9068 | J40: ='Manual Data'!J41 -> 9574 | ... L40: ='Manual Data'!L41 -> 11315 | M40: =FORECAST(M$3,$C40:$L40,$C$3:$L$3) -> 11623.928 | N40: =FORECAST(N$3,$C40:$L40,$C$3:$L$3) -> 12227.426 | O40: =FORECAST(O$3,$C40:$L40,$C$3:$L$3) -> 12830.925 | P40: =FORECAST(P$3,$C40:$L40,$C$3:$L$3) -> 13434.424 | Q40: =FORECAST(Q$3,$C40:$L40,$C$3:$L$3) -> 14037.923
B42: Total Liabilities | C42: =SUM(C36:C40) -> 14793 | D42: =SUM(D36:D40) -> 15706 | E42: =SUM(E36:E40) -> 17862 | F42: =SUM(F36:F40) -> 18629 | G42: =SUM(G36:G40) -> 20153 | H42: =SUM(H36:H40) -> 68740 | I42: =SUM(I36:I40) -> 70506 | J42: =SUM(J36:J40) -> 73077 | ... Q42: =SUM(Q36:Q40) -> 132429.16
B44: ='Data Sheet'!A62 -> Net Block | C44: ='Data Sheet'!B62 -> 3258 | D44: ='Data Sheet'!C62 -> 4419 | E44: ='Data Sheet'!D62 -> 4528 | F44: ='Data Sheet'!E62 -> 4715 | G44: ='Data Sheet'!F62 -> 5479 | H44: ='Data Sheet'!G62 -> 51443 | I44: ='Data Sheet'!H62 -> 51473 | ... L44: ='Data Sheet'!K62 -> 54335 | M44: =FORECAST(M$3,$C44:$L44,$C$3:$L$3) -> 69669.497 | N44: =FORECAST(N$3,$C44:$L44,$C$3:$L$3) -> 77130.909 | O44: =FORECAST(O$3,$C44:$L44,$C$3:$L$3) -> 84592.322 | P44: =FORECAST(P$3,$C44:$L44,$C$3:$L$3) -> 92053.734 | Q44: =FORECAST(Q$3,$C44:$L44,$C$3:$L$3) -> 99515.146
B45: ='Data Sheet'!A63 -> Capital Work in Progress | C45: ='Data Sheet'!B63 -> 408 | D45: ='Data Sheet'!C63 -> 229 | E45: ='Data Sheet'!D63 -> 461 | F45: ='Data Sheet'!E63 -> 406 | G45: ='Data Sheet'!F63 -> 597 | H45: ='Data Sheet'!G63 -> 745 | I45: ='Data Sheet'!H63 -> 1313 | ... L45: ='Data Sheet'!K63 -> 1009 | M45: =FORECAST(M$3,$C45:$L45,$C$3:$L$3) -> 1305.9454 | N45: =FORECAST(N$3,$C45:$L45,$C$3:$L$3) -> 1410.1459 | O45: =FORECAST(O$3,$C45:$L45,$C$3:$L$3) -> 1514.3464 | P45: =FORECAST(P$3,$C45:$L45,$C$3:$L$3) -> 1618.5469 | Q45: =FORECAST(Q$3,$C45:$L45,$C$3:$L$3) -> 1722.7474
B46: ='Data Sheet'!A64 -> Investments | C46: ='Data Sheet'!B64 -> 2592 | D46: ='Data Sheet'!C64 -> 3794 | E46: ='Data Sheet'!D64 -> 2873 | F46: ='Data Sheet'!E64 -> 2716 | G46: ='Data Sheet'!F64 -> 1255 | H46: ='Data Sheet'!G64 -> 2709 | I46: ='Data Sheet'!H64 -> 3521 | ... L46: ='Data Sheet'!K64 -> 3810 | M46: =FORECAST(M$3,$C46:$L46,$C$3:$L$3) -> 3767.4404 | N46: =FORECAST(N$3,$C46:$L46,$C$3:$L$3) -> 3892.7728 | O46: =FORECAST(O$3,$C46:$L46,$C$3:$L$3) -> 4018.1052 | P46: =FORECAST(P$3,$C46:$L46,$C$3:$L$3) -> 4143.4377 | Q46: =FORECAST(Q$3,$C46:$L46,$C$3:$L$3) -> 4268.7701
B47: ='Data Sheet'!A65 -> Other Assets | C47: ='Data Sheet'!B65-SUM('Data Sheet'!B67:B69) -> 1536 | D47: ='Data Sheet'!C65-SUM('Data Sheet'!C67:C69) -> 1810 | E47: ='Data Sheet'!D65-SUM('Data Sheet'!D67:D69) -> 2692 | F47: ='Data Sheet'!E65-SUM('Data Sheet'!E67:E69) -> 2645 | G47: ='Data Sheet'!F65-SUM('Data Sheet'!F67:F69) -> 3793 | H47: ='Data Sheet'!G65-SUM('Data Sheet'!G67:G69) -> 4035 | I47: ='Data Sheet'!H65-SUM('Data Sheet'!H67:H69) -> 4021 | J47: ='Data Sheet'!I65-SUM('Data Sheet'!I67:I69) -> 4377 | ... L47: ='Data Sheet'!K65-SUM('Data Sheet'!K67:K69) -> 4921 | M47: =FORECAST(M$3,$C47:$L47,$C$3:$L$3) -> 5508.2109 | N47: =FORECAST(N$3,$C47:$L47,$C$3:$L$3) -> 5884.9876 | O47: =FORECAST(O$3,$C47:$L47,$C$3:$L$3) -> 6261.7644 | P47: =FORECAST(P$3,$C47:$L47,$C$3:$L$3) -> 6638.5411 | Q47: =FORECAST(Q$3,$C47:$L47,$C$3:$L$3) -> 7015.3179
B48: Total Non Current Assets | C48: =SUM(C44:C47) -> 7794 | D48: =SUM(D44:D47) -> 10252 | E48: =SUM(E44:E47) -> 10554 | F48: =SUM(F44:F47) -> 10482 | G48: =SUM(G44:G47) -> 11124 | H48: =SUM(H44:H47) -> 58932 | I48: =SUM(I44:I47) -> 60328 | J48: =SUM(J44:J47) -> 61069 | ... L48: =SUM(L44:L47) -> 64075 | M48: =FORECAST(M$3,$C48:$L48,$C$3:$L$3) -> 80251.094 | N48: =FORECAST(N$3,$C48:$L48,$C$3:$L$3) -> 88318.816 | O48: =FORECAST(O$3,$C48:$L48,$C$3:$L$3) -> 96386.538 | P48: =FORECAST(P$3,$C48:$L48,$C$3:$L$3) -> 104454.26 | Q48: =FORECAST(Q$3,$C48:$L48,$C$3:$L$3) -> 112521.98
B49: ='Data Sheet'!A67 -> Receivables | C49: ='Data Sheet'!B67 -> 1264 | D49: ='Data Sheet'!C67 -> 1085 | E49: ='Data Sheet'!D67 -> 1310 | F49: ='Data Sheet'!E67 -> 1816 | G49: ='Data Sheet'!F67 -> 1149 | H49: ='Data Sheet'!G67 -> 1758 | I49: ='Data Sheet'!H67 -> 2236 | ... L49: ='Data Sheet'!K67 -> 3819 | M49: =FORECAST(M$3,$C49:$L49,$C$3:$L$3) -> 3620.9141 | N49: =FORECAST(N$3,$C49:$L49,$C$3:$L$3) -> 3906.128 | O49: =FORECAST(O$3,$C49:$L49,$C$3:$L$3) -> 4191.3418 | P49: =FORECAST(P$3,$C49:$L49,$C$3:$L$3) -> 4476.5557 | Q49: =FORECAST(Q$3,$C49:$L49,$C$3:$L$3) -> 4761.7696
B50: ='Data Sheet'!A68 -> Inventory | C50: ='Data Sheet'!B68 -> 2726 | D50: ='Data Sheet'!C68 -> 2541 | E50: ='Data Sheet'!D68 -> 2513 | F50: ='Data Sheet'!E68 -> 2574 | G50: ='Data Sheet'!F68 -> 2767 | H50: ='Data Sheet'!G68 -> 3579 | I50: ='Data Sheet'!H68 -> 4096 | ... L50: ='Data Sheet'!K68 -> 4415 | M50: =FORECAST(M$3,$C50:$L50,$C$3:$L$3) -> 4669.5077 | N50: =FORECAST(N$3,$C50:$L50,$C$3:$L$3) -> 4909.5656 | O50: =FORECAST(O$3,$C50:$L50,$C$3:$L$3) -> 5149.6236 | P50: =FORECAST(P$3,$C50:$L50,$C$3:$L$3) -> 5389.6815 | Q50: =FORECAST(Q$3,$C50:$L50,$C$3:$L$3) -> 5629.7394
B51: ='Data Sheet'!A69 -> Cash & Bank | C51: ='Data Sheet'!B69 -> 3009 | D51: ='Data Sheet'!C69 -> 1828 | E51: ='Data Sheet'!D69 -> 3485 | F51: ='Data Sheet'!E69 -> 3757 | G51: ='Data Sheet'!F69 -> 5113 | H51: ='Data Sheet'!G69 -> 4471 | I51: ='Data Sheet'!H69 -> 3846 | ... L51: ='Data Sheet'!K69 -> 7554 | M51: =FORECAST(M$3,$C51:$L51,$C$3:$L$3) -> 7417.1661 | N51: =FORECAST(N$3,$C51:$L51,$C$3:$L$3) -> 7941.7917 | O51: =FORECAST(O$3,$C51:$L51,$C$3:$L$3) -> 8466.4174 | P51: =FORECAST(P$3,$C51:$L51,$C$3:$L$3) -> 8991.0431 | Q51: =FORECAST(Q$3,$C51:$L51,$C$3:$L$3) -> 9515.6688
B52: Total Current Assets | C52: =SUM(C49:C51) -> 6999 | D52: =SUM(D49:D51) -> 5454 | E52: =SUM(E49:E51) -> 7308 | F52: =SUM(F49:F51) -> 8147 | G52: =SUM(G49:G51) -> 9029 | H52: =SUM(H49:H51) -> 9808 | I52: =SUM(I49:I51) -> 10178 | J52: =SUM(J49:J51) -> 12008 | ... L52: =SUM(L49:L51) -> 15788 | M52: =FORECAST(M$3,$C52:$L52,$C$3:$L$3) -> 15707.588 | N52: =FORECAST(N$3,$C52:$L52,$C$3:$L$3) -> 16757.485 | O52: =FORECAST(O$3,$C52:$L52,$C$3:$L$3) -> 17807.383 | P52: =FORECAST(P$3,$C52:$L52,$C$3:$L$3) -> 18857.28 | Q52: =FORECAST(Q$3,$C52:$L52,$C$3:$L$3) -> 19907.178
B54: Total Assets | C54: =SUM(C52,C48) -> 14793 | D54: =SUM(D52,D48) -> 15706 | E54: =SUM(E52,E48) -> 17862 | F54: =SUM(F52,F48) -> 18629 | G54: =SUM(G52,G48) -> 20153 | H54: =SUM(H52,H48) -> 68740 | I54: =SUM(I52,I48) -> 70506 | J54: =SUM(J52,J48) -> 73077 | ... L54: =SUM(L52,L48) -> 79863 | M54: =FORECAST(M$3,$C54:$L54,$C$3:$L$3) -> 95958.682 | N54: =FORECAST(N$3,$C54:$L54,$C$3:$L$3) -> 105076.3 | O54: =FORECAST(O$3,$C54:$L54,$C$3:$L$3) -> 114193.92 | P54: =FORECAST(P$3,$C54:$L54,$C$3:$L$3) -> 123311.54 | Q54: =FORECAST(Q$3,$C54:$L54,$C$3:$L$3) -> 132429.16
A57: # | B57: Cash Flow Statement
B58: Cash from Operating Activity -
B59: Profit from operations | C59: ='Manual Data'!C4 -> 6025 | D59: ='Manual Data'!D4 -> 6512 | E59: ='Manual Data'!E4 -> 7485 | F59: ='Manual Data'!F4 -> 8909 | G59: ='Manual Data'!G4 -> 9723 | H59: ='Manual Data'!H4 -> 11672 | I59: ='Manual Data'!I4 -> 12829 | J59: ='Manual Data'!J4 -> 14089 | ... L59: ='Manual Data'!L4 -> 14942 | M59: =FORECAST(M$3,$C59:$L59,$C$3:$L$3) -> 16777.071 | N59: =FORECAST(N$3,$C59:$L59,$C$3:$L$3) -> 17886.367 | O59: =FORECAST(O$3,$C59:$L59,$C$3:$L$3) -> 18995.662 | P59: =FORECAST(P$3,$C59:$L59,$C$3:$L$3) -> 20104.957 | Q59: =FORECAST(Q$3,$C59:$L59,$C$3:$L$3) -> 21214.253
...

Sheet Ratio Analysis
B2: ="Ratio Analysis for "&'Data Sheet'!$B$1 -> Ratio Analysis for HINDUSTAN UNILEVER LTD
B3: Year | C3: ='Data Sheet'!B16 -> 42460 | D3: ='Data Sheet'!C16 -> 42825 | E3: ='Data Sheet'!D16 -> 43190 | F3: ='Data Sheet'!E16 -> 43555 | G3: ='Data Sheet'!F16 -> 43921 | H3: ='Data Sheet'!G16 -> 44286 | I3: ='Data Sheet'!H16 -> 44651 | J3: ='Data Sheet'!I16 -> 45016 | ... L3: ='Data Sheet'!K16 -> 45747 | M3: ='Data Sheet'!K56+365 -> 46112 | N3: =M3+365 -> 46477 | O3: =N3+365 -> 46842 | P3: =O3+365 -> 47207 | Q3: =P3+365 -> 47572
B4: Profitability Ratios
B5: Gross Profit Margin | C5: ='Historical FS'!C12 -> 0.43385323 | D5: ='Historical FS'!D12 -> 0.43685544 | E5: ='Historical FS'!E12 -> 0.45663244 | F5: ='Historical FS'!F12 -> 0.46372424 | G5: ='Historical FS'!G12 -> 0.48183898 | H5: ='Historical FS'!H12 -> 0.46200136 | I5: ='Historical FS'!I12 -> 0.44579186 | J5: ='Historical FS'!J12 -> 0.41596236 | ... Q5: ='Historical FS'!Q12 -> 0.44835662
B6: EBITDA Margins | C6: ='Historical FS'!C17 -> 0.18362021 | D6: ='Historical FS'!D17 -> 0.19082082 | E6: ='Historical FS'!E17 -> 0.21097201 | F6: ='Historical FS'!F17 -> 0.22589672 | G6: ='Historical FS'!G17 -> 0.24786969 | H6: ='Historical FS'!H17 -> 0.24721443 | I6: ='Historical FS'!I17 -> 0.24514739 | J6: ='Historical FS'!J17 -> 0.23352592 | ... Q6: ='Historical FS'!Q17 -> 0.25413292
B7: EBIT Margins | C7: ='Historical FS'!C22 -> 0.17265271 | D7: ='Historical FS'!D22 -> 0.17779386 | E7: ='Historical FS'!E22 -> 0.19634266 | F7: ='Historical FS'!F22 -> 0.21152379 | G7: ='Historical FS'!G22 -> 0.22268306 | H7: ='Historical FS'!H22 -> 0.22437697 | I7: ='Historical FS'!I22 -> 0.22434504 | J7: ='Historical FS'!J22 -> 0.21475735 | ... Q7: ='Historical FS'!Q22 -> 0.23053689
B8: Net Profit Margins | C8: ='Historical FS'!C32 -> 0.11386938 | D8: ='Historical FS'!D32 -> 0.11712201 | E8: ='Historical FS'!E32 -> 0.13712196 | F8: ='Historical FS'!F32 -> 0.14596795 | G8: ='Historical FS'!G32 -> 0.15916346 | H8: ='Historical FS'!H32 -> 0.16647529 | I8: ='Historical FS'!I32 -> 0.16537009 | J8: ='Historical FS'!J32 -> 0.16003632 | ... Q8: ='Historical FS'!Q32 -> 0.16814388
B9: Return on Assets | C9: ='Historical FS'!C31/'Historical FS'!C54 -> 0.24775232 | D9: ='Historical FS'!D31/'Historical FS'!D54 -> 0.24729403 | E9: ='Historical FS'!E31/'Historical FS'!E54 -> 0.27286978 | F9: ='Historical FS'!F31/'Historical FS'!F54 -> 0.30801439 | G9: ='Historical FS'!G31/'Historical FS'!G54 -> 0.3141964 | H9: ='Historical FS'!H31/'Historical FS'!H54 -> 0.11389293 | I9: ='Historical FS'!I31/'Historical FS'!I54 -> 0.12301081 | J9: ='Historical FS'!J31/'Historical FS'!J54 -> 0.13266828 | ... Q9: ='Historical FS'!Q31/'Historical FS'!Q54 -> 0.10665031
B10: Return on Equity | C10: ='Historical FS'!C31/SUM('Historical FS'!C36:C37) -> 0.55758406 | D10: ='Historical FS'!D31/SUM('Historical FS'!D36:D37) -> 0.57591934 | E10: ='Historical FS'!E31/SUM('Historical FS'!E36:E37) -> 0.66941354 | F10: ='Historical FS'!F31/SUM('Historical FS'!F36:F37) -> 0.72937587 | G10: ='Historical FS'!G31/SUM('Historical FS'!G36:G37) -> 0.76947381 | H10: ='Historical FS'!H31/SUM('Historical FS'!H36:H37) -> 0.16421949 | I10: ='Historical FS'!I31/SUM('Historical FS'!I36:I37) -> 0.17677993 | J10: ='Historical FS'!J31/SUM('Historical FS'!J36:J37) -> 0.19272821 | ... Q10: ='Historical FS'!Q31/SUM('Historical FS'!Q36:Q37) -> 0.15639966
B12: Solvency ratios
B13: Debt/Equity | C13: ='Historical FS'!C38/SUM('Historical FS'!C36:C37) -> 0.026928343 | D13: ='Historical FS'!D38/SUM('Historical FS'!D36:D37) -> 0.041073547 | E13: ='Historical FS'!E38/SUM('Historical FS'!E36:E37) -> 0 | F13: ='Historical FS'!F38/SUM('Historical FS'!F36:F37) -> 0.012584213 | G13: ='Historical FS'!G38/SUM('Historical FS'!G36:G37) -> 0 | H13: ='Historical FS'!H38/SUM('Historical FS'!H36:H37) -> 0 | I13: ='Historical FS'!I38/SUM('Historical FS'!I36:I37) -> 0.021259249 | J13: ='Historical FS'!J38/SUM('Historical FS'!J36:J37) -> 0.024232665 | ... Q13: ='Historical FS'!Q38/SUM('Historical FS'!Q36:Q37) -> 0.026098772
B14: Debt Ratio | C14: ='Historical FS'!C38/'Historical FS'!C54 -> 0.011965119 | D14: ='Historical FS'!D38/'Historical FS'!D54 -> 0.017636572 | E14: ='Historical FS'!E38/'Historical FS'!E54 -> 0 | F14: ='Historical FS'!F38/'Historical FS'!F54 -> 0.0053142949 | G14: ='Historical FS'!G38/'Historical FS'!G54 -> 0 | H14: ='Historical FS'!H38/'Historical FS'!H54 -> 0 | I14: ='Historical FS'!I38/'Historical FS'!I54 -> 0.014793067 | J14: ='Historical FS'!J38/'Historical FS'!J54 -> 0.016681035 | ... Q14: ='Historical FS'!Q38/'Historical FS'!Q54 -> 0.017796983
B15: Interest Coverage | C15: ='Historical FS'!C21/'Historical FS'!C24 -> 326.88235 | D15: ='Historical FS'!D21/'Historical FS'!D24 -> 168.45714 | E15: ='Historical FS'!E21/'Historical FS'!E24 -> 268.42308 | F15: ='Historical FS'!F21/'Historical FS'!F24 -> 251.9697 | G15: ='Historical FS'!G21/'Historical FS'!G24 -> 75.076271 | H15: ='Historical FS'!H21/'Historical FS'!H24 -> 90.188034 | I15: ='Historical FS'!I21/'Historical FS'!I24 -> 111 | J15: ='Historical FS'!J21/'Historical FS'!J24 -> 114.12281 | ... Q15: ='Historical FS'!Q21/'Historical FS'!Q24 -> 40.034637
B17: Efficiency Ratios
B18: Asset Turnover | C18: ='Historical FS'!C6/'Historical FS'!C54 -> 2.1757588 | D18: ='Historical FS'!D6/'Historical FS'!D54 -> 2.1114224 | E18: ='Historical FS'!E6/'Historical FS'!E54 -> 1.9899787 | F18: ='Historical FS'!F6/'Historical FS'!F54 -> 2.1101508 | G18: ='Historical FS'!G6/'Historical FS'!G54 -> 1.9740485 | H18: ='Historical FS'!H6/'Historical FS'!H54 -> 0.68414315 | I18: ='Historical FS'!I6/'Historical FS'!I54 -> 0.74385159 | J18: ='Historical FS'!J6/'Historical FS'!J54 -> 0.8289886 | ... Q18: ='Historical FS'!Q6/'Historical FS'!Q54 -> 0.63428005
B19: Inventory Turnover | C19: ='Historical FS'!C9/'Historical FS'!C50 -> 6.6845194 | D19: ='Historical FS'!D9/'Historical FS'!D50 -> 7.3494687 | E19: ='Historical FS'!E9/'Historical FS'!E50 -> 7.6856347 | F19: ='Historical FS'!F9/'Historical FS'!F50 -> 8.1899767 | G19: ='Historical FS'!G9/'Historical FS'!G50 -> 7.4499458 | H19: ='Historical FS'!H9/'Historical FS'!H50 -> 7.0692931 | I19: ='Historical FS'!I9/'Historical FS'!I50 -> 7.0961914 | J19: ='Historical FS'!J9/'Historical FS'!J50 -> 8.3229828 | ... Q19: ='Historical FS'!Q9/'Historical FS'!Q50 -> 8.2306625
B20: Recievables Turnover | C20: ='Historical FS'!C6/'Historical FS'!C49 -> 25.463608 | D20: ='Historical FS'!D6/'Historical FS'!D49 -> 30.564055 | E20: ='Historical FS'!E6/'Historical FS'!E49 -> 27.133588 | F20: ='Historical FS'!F6/'Historical FS'!F49 -> 21.646476 | G20: ='Historical FS'!G6/'Historical FS'!G49 -> 34.624021 | H20: ='Historical FS'!H6/'Historical FS'!H49 -> 26.750853 | I20: ='Historical FS'!I6/'Historical FS'!I49 -> 23.455277 | J20: ='Historical FS'!J6/'Historical FS'!J49 -> 19.675219 | ... Q20: ='Historical FS'!Q6/'Historical FS'!Q49 -> 17.639907
B21: Payable Turnover | C21: ='Historical FS'!C9/'Historical FS'!C40 -> 3.205277 | D21: ='Historical FS'!D9/'Historical FS'!D40 -> 3.0189137 | E21: ='Historical FS'!E9/'Historical FS'!E40 -> 2.6937238 | F21: ='Historical FS'!F9/'Historical FS'!F40 -> 2.9254788 | G21: ='Historical FS'!G9/'Historical FS'!G40 -> 2.7357664 | H21: ='Historical FS'!H9/'Historical FS'!H40 -> 2.8744603 | I21: ='Historical FS'!I9/'Historical FS'!I40 -> 3.2053375 | J21: ='Historical FS'!J9/'Historical FS'!J40 -> 3.6955296 | ... Q21: ='Historical FS'!Q9/'Historical FS'!Q40 -> 3.3008078
B22: Fixed Asset Turnover | C22: ='Historical FS'!C6/'Historical FS'!C44 -> 9.8790669 | D22: ='Historical FS'!D6/'Historical FS'!D44 -> 7.5044128 | E22: ='Historical FS'!E6/'Historical FS'!E44 -> 7.8500442 | F22: ='Historical FS'!F6/'Historical FS'!F44 -> 8.3372216 | G22: ='Historical FS'!G6/'Historical FS'!G44 -> 7.2609965 | H22: ='Historical FS'!H6/'Historical FS'!H44 -> 0.91417686 | I22: ='Historical FS'!I6/'Historical FS'!I44 -> 1.0189031 | J22: ='Historical FS'!J6/'Historical FS'!J44 -> 1.1500057 | ... Q22: ='Historical FS'!Q6/'Historical FS'!Q44 -> 0.84406422
B24: Liquidity Ratios
B25: Current Ratio | I25: ='Historical FS'!I52/'Manual Data'!N37 -> 0.90230496 | J25: ='Historical FS'!J52/'Manual Data'!O37 -> 0.99833721 | K25: ='Historical FS'!K52/'Manual Data'!P37 -> 1.1321839 | L25: ='Historical FS'!L52/'Manual Data'!Q37 -> 0.95470763 | M25: =FORECAST(M$3,$I25:$L25,$I$3:$L$3) -> 1.069655 | N25: =FORECAST(N$3,$I25:$L25,$I$3:$L$3) -> 1.0987477 | O25: =FORECAST(O$3,$I25:$L25,$I$3:$L$3) -> 1.1278404 | P25: =FORECAST(P$3,$I25:$L25,$I$3:$L$3) -> 1.1569331 | Q25: =FORECAST(Q$3,$I25:$L25,$I$3:$L$3) -> 1.1860257
B26: Quick Ratio | I26: =('Historical FS'!I52-'Historical FS'!I50)/'Manual Data'!N37 -> 0.5391844 | J26: =('Historical FS'!J52-'Historical FS'!J50)/'Manual Data'!O37 -> 0.64491187 | K26: =('Historical FS'!K52-'Historical FS'!K50)/'Manual Data'!P37 -> 0.81981982 | L26: =('Historical FS'!L52-'Historical FS'!L50)/'Manual Data'!Q37 -> 0.68773054 | M26: =FORECAST(M$3,$I26:$L26,$I$3:$L$3) -> 0.82801474 | N26: =FORECAST(N$3,$I26:$L26,$I$3:$L$3) -> 0.890022 | O26: =FORECAST(O$3,$I26:$L26,$I$3:$L$3) -> 0.95202926 | P26: =FORECAST(P$3,$I26:$L26,$I$3:$L$3) -> 1.0140365 | Q26: =FORECAST(Q$3,$I26:$L26,$I$3:$L$3) -> 1.0760438
B27: Cash Ratio | I27: ='Historical FS'!I51/'Manual Data'!N37 -> 0.34095745 | J27: ='Historical FS'!J51/'Manual Data'!O37 -> 0.38892584 | K27: ='Historical FS'!K51/'Manual Data'!P37 -> 0.5870612 | L27: ='Historical FS'!L51/'Manual Data'!Q37 -> 0.45679386 | M27: =FORECAST(M$3,$I27:$L27,$I$3:$L$3) -> 0.57983648 | N27: =FORECAST(N$3,$I27:$L27,$I$3:$L$3) -> 0.63436735 | O27: =FORECAST(O$3,$I27:$L27,$I$3:$L$3) -> 0.68889823 | P27: =FORECAST(P$3,$I27:$L27,$I$3:$L$3) -> 0.74342911 | Q27: =FORECAST(Q$3,$I27:$L27,$I$3:$L$3) -> 0.79795998
B29: Market Ratios
B30: Earning per Share | I30: ='Historical FS'!C31/'Data Sheet'!B93 -> 16.937012 | J30: ='Historical FS'!D31/'Data Sheet'!C93 -> 17.945756 | K30: ='Historical FS'!E31/'Data Sheet'!D93 -> 22.517903 | L30: ='Historical FS'!F31/'Data Sheet'!E93 -> 26.507137 | M30: =FORECAST(M$3,$I30:$L30,$I$3:$L$3) -> 29.293593 | N30: =FORECAST(N$3,$I30:$L30,$I$3:$L$3) -> 32.618427 | O30: =FORECAST(O$3,$I30:$L30,$I$3:$L$3) -> 35.943262 | P30: =FORECAST(P$3,$I30:$L30,$I$3:$L$3) -> 39.268097 | Q30: =FORECAST(Q$3,$I30:$L30,$I$3:$L$3) -> 42.592931
B31: P/E ratio | I31: ='Data Sheet'!B90/'Ratio Analysis'!I30 -> 51.337273 | J31: ='Data Sheet'!C90/'Ratio Analysis'!J30 -> 50.805884 | K31: ='Data Sheet'!D90/'Ratio Analysis'!K30 -> 59.212886 | L31: ='Data Sheet'!E90/'Ratio Analysis'!L30 -> 64.390205 | M31: =FORECAST(M$3,$I31:$L31,$I$3:$L$3) -> 68.323163 | N31: =FORECAST(N$3,$I31:$L31,$I$3:$L$3) -> 73.0752 | O31: =FORECAST(O$3,$I31:$L31,$I$3:$L$3) -> 77.827237 | P31: =FORECAST(P$3,$I31:$L31,$I$3:$L$3) -> 82.579274 | Q31: =FORECAST(Q$3,$I31:$L31,$I$3:$L$3) -> 87.33131
B32: Book value per share | I32: =SUM('Historical FS'!C36:C37)/'Data Sheet'!B93 -> 30.375711 | J32: =SUM('Historical FS'!D36:D37)/'Data Sheet'!C93 -> 31.16019 | K32: =SUM('Historical FS'!E36:E37)/'Data Sheet'!D93 -> 33.638254 | L32: =SUM('Historical FS'!F36:F37)/'Data Sheet'!E93 -> 36.342218 | M32: =FORECAST(M$3,$I32:$L32,$I$3:$L$3) -> 37.970901 | N32: =FORECAST(N$3,$I32:$L32,$I$3:$L$3) -> 40.006508 | O32: =FORECAST(O$3,$I32:$L32,$I$3:$L$3) -> 42.042116 | P32: =FORECAST(P$3,$I32:$L32,$I$3:$L$3) -> 44.077723 | Q32: =FORECAST(Q$3,$I32:$L32,$I$3:$L$3) -> 46.113331
B34: Operating Cycle Ratios
B35: (in days)
B36: Invertory Days | C36: =365/C19 -> 54.603776 | D36: =365/D19 -> 49.663454 | E36: =365/E19 -> 47.491198 | F36: =365/F19 -> 44.566671 | G36: =365/G19 -> 48.993645 | H36: =365/H19 -> 51.631754 | I36: =365/I19 -> 51.436042 | J36: =365/J19 -> 43.85447 | ... L36: =365/L19 -> 46.67019 | M36: =FORECAST(M$3,$I36:$L36,$I$3:$L$3) -> 42.767292 | N36: =FORECAST(N$3,$I36:$L36,$I$3:$L$3) -> 41.316418 | O36: =FORECAST(O$3,$I36:$L36,$I$3:$L$3) -> 39.865545 | P36: =FORECAST(P$3,$I36:$L36,$I$3:$L$3) -> 38.414671 | Q36: =FORECAST(Q$3,$I36:$L36,$I$3:$L$3) -> 36.963797
B37: Recievable Days | C37: =365/C20 -> 14.334183 | D37: =365/D20 -> 11.942133 | E37: =365/E20 -> 13.451962 | F37: =365/F20 -> 16.861867 | G37: =365/G20 -> 10.541814 | H37: =365/H20 -> 13.644425 | I37: =365/I20 -> 15.56153 | J37: =365/J20 -> 18.551255 | ... L37: =365/L20 -> 22.083538 | M37: =FORECAST(M$3,$I37:$L37,$I$3:$L$3) -> 23.135599 | N37: =FORECAST(N$3,$I37:$L37,$I$3:$L$3) -> 25.001857 | O37: =FORECAST(O$3,$I37:$L37,$I$3:$L$3) -> 26.868114 | P37: =FORECAST(P$3,$I37:$L37,$I$3:$L$3) -> 28.734372 | Q37: =FORECAST(Q$3,$I37:$L37,$I$3:$L$3) -> 30.600629
B38: Payable Days | C38: =365/C21 -> 113.87471 | D38: =365/D21 -> 120.90442 | E38: =365/E21 -> 135.50016 | F38: =365/F21 -> 124.7659 | G38: =365/G21 -> 133.41782 | H38: =365/H21 -> 126.98036 | I38: =365/I21 -> 113.87257 | J38: =365/J21 -> 98.767983 | ... L38: =365/L21 -> 119.60888 | M38: =FORECAST(M$3,$I38:$L38,$I$3:$L$3) -> 119.54244 | N38: =FORECAST(N$3,$I38:$L38,$I$3:$L$3) -> 122.75893 | O38: =FORECAST(O$3,$I38:$L38,$I$3:$L$3) -> 125.97542 | P38: =FORECAST(P$3,$I38:$L38,$I$3:$L$3) -> 129.19191 | Q38: =FORECAST(Q$3,$I38:$L38,$I$3:$L$3) -> 132.40841
B40: Cash Conversion Cycle | C40: =SUM(C36:C37)-C38 -> -44.936754 | D40: =SUM(D36:D37)-D38 -> -59.298831 | E40: =SUM(E36:E37)-E38 -> -74.556995 | F40: =SUM(F36:F37)-F38 -> -63.337364 | G40: =SUM(G36:G37)-G38 -> -73.882363 | H40: =SUM(H36:H37)-H38 -> -61.704178 | I40: =SUM(I36:I37)-I38 -> -46.874994 | J40: =SUM(J36:J37)-J38 -> -36.362258 | ... L40: =SUM(L36:L37)-L38 -> -50.855151 | M40: =FORECAST(M$3,$I40:$L40,$I$3:$L$3) -> -53.639546 | N40: =FORECAST(N$3,$I40:$L40,$I$3:$L$3) -> -56.440654 | O40: =FORECAST(O$3,$I40:$L40,$I$3:$L$3) -> -59.241763 | P40: =FORECAST(P$3,$I40:$L40,$I$3:$L$3) -> -62.042871 | Q40: =FORECAST(Q$3,$I40:$L40,$I$3:$L$3) -> -64.843979 | R40: Efficient working capital management

Sheet DCF Modelling
B2: ="WACC Calculation for "&'Data Sheet'!$B$1 -> WACC Calculation for HINDUSTAN UNILEVER LTD | E2: ="Discounted Cash Flow Statement for "&'Data Sheet'!$B$1 -> Discounted Cash Flow Statement for HINDUSTAN UNILEVER LTD | Q2: Sensitivty Analysis
F3: 1 | G3: 2 | H3: 3 | I3: 4 | J3: 5 | K3: 6 | L3: 7 | M3: 8 | N3: 9 | O3: 10 | Q3: =O18 -> 39631.653 | R3: 0.02 | S3: 0.04 | T3: 0.06 | U3: 0.08 | V3: 0.1
B4: equity(E) | C4: 5397.148 | Q4: 0.1025 | R4: 30894.197 | S4: 41579.955 | T4: 62322.896 | U4: 119942.18 | V4: 1099470
B5: debt(D) | C5: 164.8 | E5: EBIT | F5: ='Historical FS'!C21 -> 5557 | G5: ='Historical FS'!D21 -> 5896 | H5: ='Historical FS'!E21 -> 6979 | I5: ='Historical FS'!F21 -> 8315 | J5: ='Historical FS'!G21 -> 8859 | K5: ='Historical FS'!H21 -> 10552 | L5: ='Historical FS'!I21 -> 11766 | M5: ='Historical FS'!J21 -> 13010 | ... O5: ='Historical FS'!L21 -> 13488 | Q5: 0.1044 | R5: 29683.18 | S5: 39664.334 | T5: 58637.52 | U5: 108714.29 | V5: 614034.4
B6: Rf | C6: 0.0626 | E6: Tax Rate | F6: =$C$10 -> 0.28595433 | G6: =$C$10 -> 0.28595433 | H6: =$C$10 -> 0.28595433 | I6: =$C$10 -> 0.28595433 | J6: =$C$10 -> 0.28595433 | K6: =$C$10 -> 0.28595433 | L6: =$C$10 -> 0.28595433 | M6: =$C$10 -> 0.28595433 | ... O6: =$C$10 -> 0.28595433 | Q6: 0.1137 | R6: 24586.407 | S6: 31871.34 | T6: 44582.668 | U6: 72381.626 | V6: 181345.42
B7: Rm | C7: =C6+(C9*C8) -> 0.09556 | E7: Depreciation | F7: ='Historical FS'!C19 -> 353 | G7: ='Historical FS'!D19 -> 432 | H7: ='Historical FS'!E19 -> 520 | I7: ='Historical FS'!F19 -> 565 | J7: ='Historical FS'!G19 -> 1002 | K7: ='Historical FS'!H19 -> 1074 | L7: ='Historical FS'!I19 -> 1091 | M7: ='Historical FS'!J19 -> 1137 | ... O7: ='Historical FS'!L19 -> 1355 | Q7: 0.1189 | R7: 22233.499 | S7: 28415.825 | T7: 38796.675 | U7: 59851.921 | V7: 125468.53
B8: ERP | C8: 0.0412 | E8: CapEx | F8: ='Historical FS'!C72 -> -810 | G8: ='Historical FS'!D72 -> -1113 | H8: ='Historical FS'!E72 -> -895 | I8: ='Historical FS'!F72 -> -767 | J8: ='Historical FS'!G72 -> -862 | K8: ='Historical FS'!H72 -> -4163 | L8: ='Historical FS'!I72 -> -1228 | M8: ='Historical FS'!J72 -> -1192 | ... O8: ='Historical FS'!L72 -> -1275 | Q8: 0.1267 | R8: 19225.139 | S8: 24123.925 | T8: 31960.515 | U8: 46509.386 | V8: 82854.32
B9: Beta | C9: 0.8 | E9: Non- Cash WC | F9: =('Historical FS'!C49+'Historical FS'!C50)-'Historical FS'!C40 -> -1695 | G9: =('Historical FS'!D49+'Historical FS'!D50)-'Historical FS'!D40 -> -2560 | H9: =('Historical FS'!E49+'Historical FS'!E50)-'Historical FS'!E40 -> -3347 | I9: =('Historical FS'!F49+'Historical FS'!F50)-'Historical FS'!F40 -> -2816 | J9: =('Historical FS'!G49+'Historical FS'!G50)-'Historical FS'!G40 -> -3619 | K9: =('Historical FS'!H49+'Historical FS'!H50)-'Historical FS'!H40 -> -3465 | L9: =('Historical FS'!I49+'Historical FS'!I50)-'Historical FS'!I40 -> -2736 | M9: =('Historical FS'!J49+'Historical FS'!J50)-'Historical FS'!J40 -> -2244 | ... O9: =('Historical FS'!L49+'Historical FS'!L50)-'Historical FS'!L40 -> -3081 | Q9: 0.1312 | R9: 17726.3 | S9: 22037.443 | T9: 28770.578 | U9: 40763.973 | V9: 68133.516
B10: Tax Rate | C10: ='Historical FS'!L29/'Historical FS'!L26 -> 0.28595433 | E10: FCF | F10: =F5*(1-F6)+F7+F8+F9 -> 1815.9518 | G10: =G5*(1-G6)+G7+G8+G9 -> 969.01329 | H10: =H5*(1-H6)+H7+H8+H9 -> 1261.3248 | I10: =I5*(1-I6)+I7+I8+I9 -> 2919.2898 | J10: =J5*(1-J6)+J7+J8+J9 -> 2846.7306 | K10: =K5*(1-K6)+K7+K8+K9 -> 980.60994 | L10: =L5*(1-L6)+L7+L8+L9 -> 5528.4614 | M10: =M5*(1-M6)+M7+M8+M9 -> 6990.7342 | ... O10: =O5*(1-O6)+O7+O8+O9 -> 6630.048 | Q10: 0.1399 | R10: 15227.553 | S10: 18634.468 | T10: 23746.971 | U10: 32273.5 | V10: 49347.929
B11: Kd | C11: =(('Historical FS'!L76+'Historical FS'!L89)/'DCF Modelling'!C5)*(1-C9) -> 0.85558252
E12: Growth Rate | F12: 0.04
B13: Cost of equity | C13: =C6+(C7-C6)*C9 -> 0.088968 | E13: WACC | F13: =C17 -> 0.10443354
B14: ew | C14: =C4/SUM(C4:C5) -> 0.97037009 | E14: Terminal Value | F14: =(O10*(1+F12))/(F13-F12) -> 107013.37
B15: dw | C15: =C5/SUM(C4:C5) -> 0.029629907
